Exception on / [GET]
Traceback (most recent call last):
  File "C:\Users\chris.GPC\.virtualenvs\MyProjectDir-M_NNinF4\lib\site-packages\sqlalchemy\engine\base.py", line 1248, in _execute_context
    cursor, statement, parameters, context
  File "C:\Users\chris.GPC\.virtualenvs\MyProjectDir-M_NNinF4\lib\site-packages\sqlalchemy\engine\default.py", line 590, in do_execute
    cursor.execute(statement, parameters)
  File "C:\Users\chris.GPC\.virtualenvs\MyProjectDir-M_NNinF4\lib\site-packages\pymysql\cursors.py", line 170, in execute
    result = self._query(query)
  File "C:\Users\chris.GPC\.virtualenvs\MyProjectDir-M_NNinF4\lib\site-packages\pymysql\cursors.py", line 328, in _query
    conn.query(q)
  File "C:\Users\chris.GPC\.virtualenvs\MyProjectDir-M_NNinF4\lib\site-packages\pymysql\connections.py", line 517, in query
    self._affected_rows = self._read_query_result(unbuffered=unbuffered)
  File "C:\Users\chris.GPC\.virtualenvs\MyProjectDir-M_NNinF4\lib\site-packages\pymysql\connections.py", line 732, in _read_query_result
    result.read()
  File "C:\Users\chris.GPC\.virtualenvs\MyProjectDir-M_NNinF4\lib\site-packages\pymysql\connections.py", line 1075, in read
    first_packet = self.connection._read_packet()
  File "C:\Users\chris.GPC\.virtualenvs\MyProjectDir-M_NNinF4\lib\site-packages\pymysql\connections.py", line 684, in _read_packet
    packet.check_error()
  File "C:\Users\chris.GPC\.virtualenvs\MyProjectDir-M_NNinF4\lib\site-packages\pymysql\protocol.py", line 220, in check_error
    err.raise_mysql_exception(self._data)
  File "C:\Users\chris.GPC\.virtualenvs\MyProjectDir-M_NNinF4\lib\site-packages\pymysql\err.py", line 109, in raise_mysql_exception
    raise errorclass(errno, errval)
pymysql.err.ProgrammingError: (1146, "Table 'flask_str.users' doesn't exist")

The above exception was the direct cause of the following exception:

Traceback (most recent call last):
  File "C:\Users\chris.GPC\.virtualenvs\MyProjectDir-M_NNinF4\lib\site-packages\flask\app.py", line 2446, in wsgi_app
    response = self.full_dispatch_request()
  File "C:\Users\chris.GPC\.virtualenvs\MyProjectDir-M_NNinF4\lib\site-packages\flask\app.py", line 1951, in full_dispatch_request
    rv = self.handle_user_exception(e)
  File "C:\Users\chris.GPC\.virtualenvs\MyProjectDir-M_NNinF4\lib\site-packages\flask\app.py", line 1820, in handle_user_exception
    reraise(exc_type, exc_value, tb)
  File "C:\Users\chris.GPC\.virtualenvs\MyProjectDir-M_NNinF4\lib\site-packages\flask\_compat.py", line 39, in reraise
    raise value
  File "C:\Users\chris.GPC\.virtualenvs\MyProjectDir-M_NNinF4\lib\site-packages\flask\app.py", line 1949, in full_dispatch_request
    rv = self.dispatch_request()
  File "C:\Users\chris.GPC\.virtualenvs\MyProjectDir-M_NNinF4\lib\site-packages\flask\app.py", line 1935, in dispatch_request
    return self.view_functions[rule.endpoint](**req.view_args)
  File "P:\Projects\research_n_study\python\flask_project_structure\MyProjectDir\app\__init__.py", line 62, in index
    if current_user.id:
  File "C:\Users\chris.GPC\.virtualenvs\MyProjectDir-M_NNinF4\lib\site-packages\werkzeug\local.py", line 348, in __getattr__
    return getattr(self._get_current_object(), name)
  File "C:\Users\chris.GPC\.virtualenvs\MyProjectDir-M_NNinF4\lib\site-packages\werkzeug\local.py", line 307, in _get_current_object
    return self.__local()
  File "C:\Users\chris.GPC\.virtualenvs\MyProjectDir-M_NNinF4\lib\site-packages\flask_login\utils.py", line 26, in <lambda>
    current_user = LocalProxy(lambda: _get_user())
  File "C:\Users\chris.GPC\.virtualenvs\MyProjectDir-M_NNinF4\lib\site-packages\flask_login\utils.py", line 335, in _get_user
    current_app.login_manager._load_user()
  File "C:\Users\chris.GPC\.virtualenvs\MyProjectDir-M_NNinF4\lib\site-packages\flask_login\login_manager.py", line 359, in _load_user
    return self.reload_user()
  File "C:\Users\chris.GPC\.virtualenvs\MyProjectDir-M_NNinF4\lib\site-packages\flask_login\login_manager.py", line 321, in reload_user
    user = self.user_callback(user_id)
  File "P:\Projects\research_n_study\python\flask_project_structure\MyProjectDir\app\module\views.py", line 25, in user_loader
    return Users.query.get(int(user_id))
  File "C:\Users\chris.GPC\.virtualenvs\MyProjectDir-M_NNinF4\lib\site-packages\sqlalchemy\orm\query.py", line 1004, in get
    return self._get_impl(ident, loading.load_on_pk_identity)
  File "C:\Users\chris.GPC\.virtualenvs\MyProjectDir-M_NNinF4\lib\site-packages\sqlalchemy\orm\query.py", line 1121, in _get_impl
    return db_load_fn(self, primary_key_identity)
  File "C:\Users\chris.GPC\.virtualenvs\MyProjectDir-M_NNinF4\lib\site-packages\sqlalchemy\orm\loading.py", line 287, in load_on_pk_identity
    return q.one()
  File "C:\Users\chris.GPC\.virtualenvs\MyProjectDir-M_NNinF4\lib\site-packages\sqlalchemy\orm\query.py", line 3360, in one
    ret = self.one_or_none()
  File "C:\Users\chris.GPC\.virtualenvs\MyProjectDir-M_NNinF4\lib\site-packages\sqlalchemy\orm\query.py", line 3329, in one_or_none
    ret = list(self)
  File "C:\Users\chris.GPC\.virtualenvs\MyProjectDir-M_NNinF4\lib\site-packages\sqlalchemy\orm\query.py", line 3405, in __iter__
    return self._execute_and_instances(context)
  File "C:\Users\chris.GPC\.virtualenvs\MyProjectDir-M_NNinF4\lib\site-packages\sqlalchemy\orm\query.py", line 3430, in _execute_and_instances
    result = conn.execute(querycontext.statement, self._params)
  File "C:\Users\chris.GPC\.virtualenvs\MyProjectDir-M_NNinF4\lib\site-packages\sqlalchemy\engine\base.py", line 984, in execute
    return meth(self, multiparams, params)
  File "C:\Users\chris.GPC\.virtualenvs\MyProjectDir-M_NNinF4\lib\site-packages\sqlalchemy\sql\elements.py", line 293, in _execute_on_connection
    return connection._execute_clauseelement(self, multiparams, params)
  File "C:\Users\chris.GPC\.virtualenvs\MyProjectDir-M_NNinF4\lib\site-packages\sqlalchemy\engine\base.py", line 1103, in _execute_clauseelement
    distilled_params,
  File "C:\Users\chris.GPC\.virtualenvs\MyProjectDir-M_NNinF4\lib\site-packages\sqlalchemy\engine\base.py", line 1288, in _execute_context
    e, statement, parameters, cursor, context
  File "C:\Users\chris.GPC\.virtualenvs\MyProjectDir-M_NNinF4\lib\site-packages\sqlalchemy\engine\base.py", line 1482, in _handle_dbapi_exception
    sqlalchemy_exception, with_traceback=exc_info[2], from_=e
  File "C:\Users\chris.GPC\.virtualenvs\MyProjectDir-M_NNinF4\lib\site-packages\sqlalchemy\util\compat.py", line 178, in raise_
    raise exception
  File "C:\Users\chris.GPC\.virtualenvs\MyProjectDir-M_NNinF4\lib\site-packages\sqlalchemy\engine\base.py", line 1248, in _execute_context
    cursor, statement, parameters, context
  File "C:\Users\chris.GPC\.virtualenvs\MyProjectDir-M_NNinF4\lib\site-packages\sqlalchemy\engine\default.py", line 590, in do_execute
    cursor.execute(statement, parameters)
  File "C:\Users\chris.GPC\.virtualenvs\MyProjectDir-M_NNinF4\lib\site-packages\pymysql\cursors.py", line 170, in execute
    result = self._query(query)
  File "C:\Users\chris.GPC\.virtualenvs\MyProjectDir-M_NNinF4\lib\site-packages\pymysql\cursors.py", line 328, in _query
    conn.query(q)
  File "C:\Users\chris.GPC\.virtualenvs\MyProjectDir-M_NNinF4\lib\site-packages\pymysql\connections.py", line 517, in query
    self._affected_rows = self._read_query_result(unbuffered=unbuffered)
  File "C:\Users\chris.GPC\.virtualenvs\MyProjectDir-M_NNinF4\lib\site-packages\pymysql\connections.py", line 732, in _read_query_result
    result.read()
  File "C:\Users\chris.GPC\.virtualenvs\MyProjectDir-M_NNinF4\lib\site-packages\pymysql\connections.py", line 1075, in read
    first_packet = self.connection._read_packet()
  File "C:\Users\chris.GPC\.virtualenvs\MyProjectDir-M_NNinF4\lib\site-packages\pymysql\connections.py", line 684, in _read_packet
    packet.check_error()
  File "C:\Users\chris.GPC\.virtualenvs\MyProjectDir-M_NNinF4\lib\site-packages\pymysql\protocol.py", line 220, in check_error
    err.raise_mysql_exception(self._data)
  File "C:\Users\chris.GPC\.virtualenvs\MyProjectDir-M_NNinF4\lib\site-packages\pymysql\err.py", line 109, in raise_mysql_exception
    raise errorclass(errno, errval)
sqlalchemy.exc.ProgrammingError: (pymysql.err.ProgrammingError) (1146, "Table 'flask_str.users' doesn't exist")
[SQL: SELECT users.id AS users_id, users.date_created AS users_date_created, users.date_modified AS users_date_modified, users.name AS users_name, users.surname AS users_surname, users.email AS users_email, users.password AS users_password, users.image AS users_image, users.`role` AS users_role 
FROM users 
WHERE users.id = %(param_1)s]
[parameters: {'param_1': 2}]
(Background on this error at: http://sqlalche.me/e/f405)
