Exception on /public/signup [POST]
Traceback (most recent call last):
  File "/home/ubuntu/.local/share/virtualenvs/sfp-39E9eSVQ/lib/python3.8/site-packages/flask/app.py", line 2446, in wsgi_app
    response = self.full_dispatch_request()
  File "/home/ubuntu/.local/share/virtualenvs/sfp-39E9eSVQ/lib/python3.8/site-packages/flask/app.py", line 1951, in full_dispatch_request
    rv = self.handle_user_exception(e)
  File "/home/ubuntu/.local/share/virtualenvs/sfp-39E9eSVQ/lib/python3.8/site-packages/flask/app.py", line 1820, in handle_user_exception
    reraise(exc_type, exc_value, tb)
  File "/home/ubuntu/.local/share/virtualenvs/sfp-39E9eSVQ/lib/python3.8/site-packages/flask/_compat.py", line 39, in reraise
    raise value
  File "/home/ubuntu/.local/share/virtualenvs/sfp-39E9eSVQ/lib/python3.8/site-packages/flask/app.py", line 1949, in full_dispatch_request
    rv = self.dispatch_request()
  File "/home/ubuntu/.local/share/virtualenvs/sfp-39E9eSVQ/lib/python3.8/site-packages/flask/app.py", line 1935, in dispatch_request
    return self.view_functions[rule.endpoint](**req.view_args)
  File "/var/www/sfp/app/module/views.py", line 38, in signup
    image_filename = photos.save(form.image.data)
  File "/home/ubuntu/.local/share/virtualenvs/sfp-39E9eSVQ/lib/python3.8/site-packages/flask_uploads.py", line 422, in save
    os.makedirs(target_folder)
  File "/usr/lib/python3.6/os.py", line 210, in makedirs
    makedirs(head, mode, exist_ok)
  File "/usr/lib/python3.6/os.py", line 210, in makedirs
    makedirs(head, mode, exist_ok)
  File "/usr/lib/python3.6/os.py", line 210, in makedirs
    makedirs(head, mode, exist_ok)
  File "/usr/lib/python3.6/os.py", line 220, in makedirs
    mkdir(name, mode)
PermissionError: [Errno 13] Permission denied: '/var/www/mfp'
